<?xml version="1.0"?>
<robot name="box_bot">

  <link name="base_link">
    <visual>
      <geometry><box size="0.6 0.4 0.2"/></geometry>
    </visual>
    <collision>
      <geometry><box size="0.6 0.4 0.2"/></geometry>
    </collision>
    <inertial>
      <mass value="5.0"/>
      <inertia ixx="0.08" ixy="0" ixz="0" iyy="0.16" iyz="0" izz="0.21"/>
    </inertial>
  </link>

  <link name="front_left_wheel">
    <visual>
      <geometry><cylinder length="0.05" radius="0.1"/></geometry>
    </visual>
    <collision>
      <geometry><cylinder length="0.05" radius="0.1"/></geometry>
    </collision>
    <inertial>
      <mass value="0.5"/>
      <inertia ixx="0.001" ixy="0" ixz="0" iyy="0.001" iyz="0" izz="0.002"/>
    </inertial>
  </link>

  <joint name="front_left_wheel_joint" type="continuous">
    <parent link="base_link"/>
    <child link="front_left_wheel"/>
    <origin xyz="0.2 0.25 -0.1" rpy="-1.5707 0 0"/>
    <axis xyz="0 1 0"/>
  </joint>

  <link name="front_right_wheel">
    <visual>
      <geometry><cylinder length="0.05" radius="0.1"/></geometry>
    </visual>
    <collision>
      <geometry><cylinder length="0.05" radius="0.1"/></geometry>
    </collision>
    <inertial>
      <mass value="0.5"/>
      <inertia ixx="0.001" ixy="0" ixz="0" iyy="0.001" iyz="0" izz="0.002"/>
    </inertial>
  </link>

  <joint name="front_right_wheel_joint" type="continuous">
    <parent link="base_link"/>
    <child link="front_right_wheel"/>
    <origin xyz="0.2 -0.25 -0.1" rpy="-1.5707 0 0"/>
    <axis xyz="0 1 0"/>
  </joint>

  <link name="back_left_wheel">
    <visual>
      <geometry><cylinder length="0.05" radius="0.1"/></geometry>
    </visual>
    <collision>
      <geometry><cylinder length="0.05" radius="0.1"/></geometry>
    </collision>
    <inertial>
      <mass value="0.5"/>
      <inertia ixx="0.001" ixy="0" ixz="0" iyy="0.001" iyz="0" izz="0.002"/>
    </inertial>
  </link>

  <joint name="back_left_wheel_joint" type="continuous">
    <parent link="base_link"/>
    <child link="back_left_wheel"/>
    <origin xyz="-0.2 0.25 -0.1" rpy="-1.5707 0 0"/>
    <axis xyz="0 1 0"/>
  </joint>

  <link name="back_right_wheel">
    <visual>
      <geometry><cylinder length="0.05" radius="0.1"/></geometry>
    </visual>
    <collision>
      <geometry><cylinder length="0.05" radius="0.1"/></geometry>
    </collision>
    <inertial>
      <mass value="0.5"/>
      <inertia ixx="0.001" ixy="0" ixz="0" iyy="0.001" iyz="0" izz="0.002"/>
    </inertial>
  </link>

  <joint name="back_right_wheel_joint" type="continuous">
    <parent link="base_link"/>
    <child link="back_right_wheel"/>
    <origin xyz="-0.2 -0.25 -0.1" rpy="-1.5707 0 0"/>
    <axis xyz="0 1 0"/>
  </joint>

  <gazebo>
    <plugin
      filename="ignition-gazebo-diff-drive-system"
      name="ignition::gazebo::systems::DiffDrive">
      <left_joint>front_left_wheel_joint</left_joint>
      <left_joint>back_left_wheel_joint</left_joint>
      <right_joint>front_right_wheel_joint</right_joint>
      <right_joint>back_right_wheel_joint</right_joint>
      
      <wheel_separation>0.5</wheel_separation>
      <wheel_radius>0.1</wheel_radius>
      <topic>cmd_vel</topic>
      <odom_topic>odom</odom_topic>
      <frame_id>odom</frame_id>
      <child_frame_id>base_link</child_frame_id>
    </plugin>
  </gazebo>

</robot>
