<?xml version="1.0"?>
<robot name="box_bot">

  <link name="base_footprint"/>

  <joint name="base_footprint_joint" type="fixed">
    <parent link="base_footprint"/>
    <child link="base_link"/>
    <origin xyz="0 0 0.1" rpy="0 0 0"/> </joint>

  <link name="base_link">
    <visual>
      <geometry>
        <box size="0.60 0.40 0.20"/>
      </geometry>
      <material name="Grey">
        <color rgba="0.5 0.5 0.5 1"/>
      </material>
    </visual>
    <collision>
      <geometry>
        <box size="0.60 0.40 0.20"/>
      </geometry>
    </collision>
    <inertial>
      <mass value="10.0"/>
      <inertia ixx="0.2" ixy="0.0" ixz="0.0" iyy="0.4" iyz="0.0" izz="0.5"/>
    </inertial>
  </link>

  <link name="front_left_wheel">
    <visual>
      <origin xyz="0 0 0" rpy="1.5708 0 0"/>
      <geometry><cylinder radius="0.10" length="0.05"/></geometry>
    </visual>
    <collision>
      <origin xyz="0 0 0" rpy="1.5708 0 0"/>
      <geometry><cylinder radius="0.10" length="0.05"/></geometry>
    </collision>
    <inertial>
      <mass value="0.5"/><inertia ixx="0.001" ixy="0" ixz="0" iyy="0.001" iyz="0" izz="0.001"/>
    </inertial>
  </link>

  <joint name="front_left_wheel_joint" type="continuous">
    <parent link="base_link"/><child link="front_left_wheel"/>
    <origin xyz="0.20 0.225 0" rpy="0 0 0"/><axis xyz="0 1 0"/>
  </joint>

  <link name="front_right_wheel">
    <visual>
      <origin xyz="0 0 0" rpy="1.5708 0 0"/>
      <geometry><cylinder radius="0.10" length="0.05"/></geometry>
    </visual>
    <collision>
      <origin xyz="0 0 0" rpy="1.5708 0 0"/>
      <geometry><cylinder radius="0.10" length="0.05"/></geometry>
    </collision>
    <inertial>
      <mass value="0.5"/><inertia ixx="0.001" ixy="0" ixz="0" iyy="0.001" iyz="0" izz="0.001"/>
    </inertial>
  </link>

  <joint name="front_right_wheel_joint" type="continuous">
    <parent link="base_link"/><child link="front_right_wheel"/>
    <origin xyz="0.20 -0.225 0" rpy="0 0 0"/><axis xyz="0 1 0"/>
  </joint>

  <link name="rear_left_wheel">
    <visual>
      <origin xyz="0 0 0" rpy="1.5708 0 0"/>
      <geometry><cylinder radius="0.10" length="0.05"/></geometry>
    </visual>
    <collision>
      <origin xyz="0 0 0" rpy="1.5708 0 0"/>
      <geometry><cylinder radius="0.10" length="0.05"/></geometry>
    </collision>
    <inertial>
      <mass value="0.5"/><inertia ixx="0.001" ixy="0" ixz="0" iyy="0.001" iyz="0" izz="0.001"/>
    </inertial>
  </link>

  <joint name="rear_left_wheel_joint" type="continuous">
    <parent link="base_link"/><child link="rear_left_wheel"/>
    <origin xyz="-0.20 0.225 0" rpy="0 0 0"/><axis xyz="0 1 0"/>
  </joint>

  <link name="rear_right_wheel">
    <visual>
      <origin xyz="0 0 0" rpy="1.5708 0 0"/>
      <geometry><cylinder radius="0.10" length="0.05"/></geometry>
    </visual>
    <collision>
      <origin xyz="0 0 0" rpy="1.5708 0 0"/>
      <geometry><cylinder radius="0.10" length="0.05"/></geometry>
    </collision>
    <inertial>
      <mass value="0.5"/><inertia ixx="0.001" ixy="0" ixz="0" iyy="0.001" iyz="0" izz="0.001"/>
    </inertial>
  </link>

  <joint name="rear_right_wheel_joint" type="continuous">
    <parent link="base_link"/><child link="rear_right_wheel"/>
    <origin xyz="-0.20 -0.225 0" rpy="0 0 0"/><axis xyz="0 1 0"/>
  </joint>

  <link name="lidar_link">
    <visual>
      <geometry><cylinder radius="0.05" length="0.1"/></geometry>
      <material name="blue"><color rgba="0 0 1 1"/></material>
    </visual>
    <collision>
      <geometry><cylinder radius="0.05" length="0.1"/></geometry>
    </collision>
    <inertial>
      <mass value="0.1"/><inertia ixx="0.0001" ixy="0" ixz="0" iyy="0.0001" iyz="0" izz="0.0001"/>
    </inertial>
  </link>

  <joint name="lidar_joint" type="fixed">
    <parent link="base_link"/>
    <child link="lidar_link"/>
    <origin xyz="0 0 0.15" rpy="0 0 0"/> </joint>

  <gazebo>
    <plugin filename="gz-sim-diff-drive-system" name="gz::sim::systems::DiffDrive">
      <left_joint>front_left_wheel_joint</left_joint>
      <left_joint>rear_left_wheel_joint</left_joint>
      <right_joint>front_right_wheel_joint</right_joint>
      <right_joint>rear_right_wheel_joint</right_joint>
      <wheel_separation>0.45</wheel_separation>
      <wheel_radius>0.10</wheel_radius>
      <topic>cmd_vel</topic>
      <odom_topic>odom</odom_topic>
      <frame_id>odom</frame_id>
      <child_frame_id>base_footprint</child_frame_id>
      <max_linear_acceleration>1.0</max_linear_acceleration>
    </plugin>

    <plugin filename="gz-sim-joint-state-publisher-system" name="gz::sim::systems::JointStatePublisher">
      <topic>joint_states</topic>
    </plugin>
  </gazebo>

  <gazebo reference="lidar_link">
    <sensor name="gpu_lidar" type="gpu_lidar">
      <update_rate>10</update_rate>
      <lidar>
        <scan>
          <horizontal>
            <samples>640</samples>
            <resolution>1</resolution>
            <min_angle>-3.14159</min_angle>
            <max_angle>3.14159</max_angle>
          </horizontal>
        </scan>
        <range>
          <min>0.1</min>
          <max>10.0</max>
        </range>
      </lidar>
      <topic>scan</topic>
      <gz_frame_id>lidar_link</gz_frame_id>
    </sensor>
  </gazebo>

</robot>
